Workbook
Name Slicer_Sector: #N/A
Name Slicer_Sector1: #N/A

Sheet All_India_Index_Upto_April23-CP
A1: Sector | B1: Year | C1: Month | D1: Cereals and products | E1: Meat and fish | F1: Egg | G1: Milk and products | H1: Oils and fats | I1: Fruits | J1: Vegetables | K1: Pulses and products | L1: Sugar and Confectionery | M1: Spices | N1: Non-alcoholic beverages | O1: Prepared meals, snacks, sweets etc. | P1: Food and beverages | Q1: Pan, tobacco and intoxicants | R1: Clothing | S1: Footwear | T1: Clothing and footwear | U1: Housing | V1: Fuel and light | W1: Household goods and services | X1: Health | Y1: Transport and communication | Z1: Recreation and amusement | AA1: Education | AB1: Personal care and effects | AC1: Miscellaneous | AD1: Food Bucket | AE1: Recreation Bucket | AF1: Housing bucket | AG1: Health bucket | AH1: clothing bucket | AI1: General index | AJ1: MoM % | AN1: Year | AQ1: Sector | AR1: Year | AS1: Month | AT1: Cereals and products | AU1: Meat and fish | AV1: Egg | AW1: Milk and products | AX1: Oils and fats | AY1: Fruits | AZ1: Vegetables | BA1: Pulses and products | BB1: Sugar and Confectionery | BC1: Spices | BD1: Non-alcoholic beverages | BE1: Prepared meals, snacks, sweets etc. | BF1: Food and beverages | BG1: Food Bucket | BH1: FOOD MOM | BI1: ABSOLUTE CHANGE % | BL1: Year | BO1: Sector | BP1: Year | BQ1: Month | BR1: Month-Year | BS1: Cereals and products | BT1: Meat and fish | BU1: Egg | BV1: Milk and products | BW1: Oils and fats | BX1: Fruits | BY1: Vegetables | BZ1: Pulses and products | CA1: Sugar and Confectionery | CB1: Spices | CC1: Non-alcoholic beverages | CD1: Prepared meals, snacks, sweets etc. | CE1: Food and beverages | CF1: Pan, tobacco and intoxicants | CG1: Clothing | CH1: Footwear | CI1: Clothing and footwear | CJ1: Housing | CK1: Fuel and light | CL1: Household goods and services | CM1: Health | CN1: Transport and communication | CO1: Recreation and amusement | CP1: Education | CQ1: Personal care and effects | CR1: Miscellaneous | CS1: Food Bucket | CT1: Recreation Bucket | CU1: Housing bucket | CV1: Health bucket | CW1: clothing bucket | CX1: General index | CY1: MoM % | CZ1: Oil Price | DB1: Cereals and products | DC1: Meat and fish | DD1: Egg | DE1: Milk and products | DF1: Oils and fats | DG1: Fruits | DH1: Vegetables | DI1: Pulses and products | DJ1: Sugar and Confectionery | DK1: Spices | DL1: Non-alcoholic beverages | DM1: Prepared meals, snacks, sweets etc. | DN1: Food and beverages | DO1: Pan, tobacco and intoxicants | DP1: Clothing | DQ1: Footwear | DR1: Clothing and footwear | DS1: Housing | DT1: Household goods and services | DU1: Health | DV1: Recreation and amusement | DW1: Personal care and effects | DX1: Miscellaneous | DY1: Transport and communication | DZ1: Education | EA1: Fuel and light
A2: Rural | B2: 2013 | C2: January | D2: 108.2 | E2: 106.3 | F2: 108.1 | G2: 104.9 | H2: 106.1 | I2: 103.9 | J2: 101.9 | K2: 106.1 | L2: 106.8 | M2: 103.1 | N2: 104.8 | O2: 106.7 | P2: 105.5 | Q2: 105.1 | R2: 106.5 | S2: 105.8 | T2: 106.4 | U2: 0 | V2: 105.5 | W2: 104.8 | X2: 104 | Y2: 103.3 | Z2: 103.4 | AA2: 103.8 | AB2: 104.7 | AC2: 104 | AD2: =AVERAGE(All_India_Index_Upto_April23_CPI_data[[#This Row],[Cereals and products]:[Food and beverages]]) -> 105.56923 | AE2: =AVERAGE(All_India_Index_Upto_April23_CPI_data[[#This Row],[Recreation and amusement]],All_India_Index_Upto_April23_CPI_data[[#This Row],[Pan, tobacco and intoxicants]]) -> 104.25 | AF2: =AVERAGE(All_India_Index_Upto_April23_CPI_data[[#This Row],[Household goods and services]],All_India_Index_Upto_April23_CPI_data[[#This Row],[Housing]]) -> 52.4 | AG2: =AVERAGE(All_India_Index_Upto_April23_CPI_data[[#This Row],[Personal care and effects]],All_India_Index_Upto_April23_CPI_data[[#This Row],[Health]]) -> 104.35 | AH2: =AVERAGE(All_India_Index_Upto_April23_CPI_data[[#This Row],[Clothing]:[Clothing and footwear]]) -> 106.23333 | AI2: 105.1 | AJ2: 0 | AN2: 2022 | AQ2: Rural | AR2: 2022 | AS2: May | AT2: 152.9 | AU2: 214.7 | AV2: 161.4 | AW2: 164.6 | AX2: 209.9 | AY2: 168 | AZ2: 160.4 | BA2: 165 | BB2: 118.9 | BC2: 186.6 | BD2: 173.2 | BE2: 180.4 | BF2: 170.8 | BG2: 171.29231 | BH2: 0 | BI2: 0 | BL2: 2021 | BO2: Rural | BP2: 2021 | BQ2: January | BR2: =DATE(BP2,MONTH(DATEVALUE("1 "&BQ2)),1) -> 44197 | BS2: 143.4 | BT2: 187.5 | BU2: 173.4 | BV2: 154 | BW2: 154.8 | BX2: 147 | BY2: 187.8 | BZ2: 159.5 | CA2: 113.8 | CB2: 164.5 | CC2: 156.1 | CD2: 164.3 | CE2: 159.6 | CF2: 184.6 | CG2: 157.5 | CH2: 152.4 | CI2: 156.8 | CJ2: 0 | CK2: 150.9 | CL2: 153.9 | CM2: 162.5 | CN2: 147.5 | CO2: 155.1 | CP2: 163.5 | CQ2: 156.2 | CR2: 155.9 | CS2: 158.9 | CT2: 169.85 | CU2: 76.95 | CV2: 159.35 | CW2: 155.56667 | CX2: 158.5 | CY2: -0.013690106 | CZ2: =VLOOKUP(BR2,'OIL PRICE'!$A$1:$B$27,2,0) -> 54.79 | DB2: =CORREL(Table2[Oil Price],Table2[Cereals and products]) -> 0.37272749 | DC2: =CORREL(Table2[Oil Price],Table2[Meat and fish]) -> 0.77941794 | DD2: =CORREL(Table2[Oil Price],Table2[Egg]) -> -0.19565754 | DE2: =CORREL(Table2[Oil Price],Table2[Milk and products]) -> 0.50622757 | DF2: =CORREL(Table2[Oil Price],Table2[Oils and fats]) -> 0.70587202 | DG2: =CORREL(Table2[Oil Price],Table2[Fruits]) -> 0.52591638 | DH2: =CORREL(Table2[Oil Price],Table2[Vegetables]) -> 0.26561441 | DI2: =CORREL(Table2[Oil Price],Table2[Pulses and products]) -> 0.27579656 | DJ2: =CORREL(Table2[Oil Price],Table2[Sugar and Confectionery]) -> 0.54543467 | DK2: =CORREL(Table2[Oil Price],Table2[Spices]) -> 0.47271898 | DL2: =CORREL(Table2[Oil Price],Table2[Non-alcoholic beverages]) -> 0.46253989 | DM2: =CORREL(Table2[Oil Price],Table2[Prepared meals, snacks, sweets etc.]) -> 0.60292677 | DN2: =CORREL(Table2[Oil Price],Table2[Food and beverages]) -> 0.63405112 | DO2: =CORREL(Table2[Oil Price],Table2[Pan, tobacco and intoxicants]) -> 0.42594326 | DP2: =CORREL(Table2[Oil Price],Table2[Clothing]) -> 0.60103705 | DQ2: =CORREL(Table2[Oil Price],Table2[Footwear]) -> 0.51937145 | DR2: =CORREL(Table2[Oil Price],Table2[Clothing and footwear]) -> 0.58895943 | DS2: =CORREL(Table2[Oil Price],Table2[Housing]) -> 0.021569988 | DT2: =CORREL(Table2[Oil Price],Table2[Household goods and services]) -> 0.57461438 | DU2: =CORREL(Table2[Oil Price],Table2[Health]) -> 0.5621766 | DV2: =CORREL(Table2[Oil Price],Table2[Recreation and amusement]) -> 0.63951952 | DW2: =CORREL(Table2[Oil Price],Table2[Personal care and effects]) -> 0.57879308 | DX2: =CORREL(Table2[Oil Price],Table2[Miscellaneous]) -> 0.60247885 | DY2: =CORREL(Table2[Transport and communication],Table2[Oil Price]) -> 0.67102304 | DZ2: =CORREL(Table2[Oil Price],Table2[Education]) -> 0.49168151 | EA2: =CORREL(Table2[Oil Price],Table2[Fuel and light]) -> 0.65882631
A3: Urban | B3: 2013 | C3: January | D3: 110.5 | E3: 109.1 | F3: 113 | G3: 103.6 | H3: 103.4 | I3: 102.3 | J3: 102.9 | K3: 105.8 | L3: 105.1 | M3: 101.8 | N3: 105.1 | O3: 107.9 | P3: 105.9 | Q3: 105.2 | R3: 105.9 | S3: 105 | T3: 105.8 | U3: 100.3 | V3: 105.4 | W3: 104.8 | X3: 104.1 | Y3: 103.2 | Z3: 102.9 | AA3: 103.5 | AB3: 104.3 | AC3: 103.7 | AD3: =AVERAGE(All_India_Index_Upto_April23_CPI_data[[#This Row],[Cereals and products]:[Food and beverages]]) -> 105.87692 | AE3: =AVERAGE(All_India_Index_Upto_April23_CPI_data[[#This Row],[Recreation and amusement]],All_India_Index_Upto_April23_CPI_data[[#This Row],[Pan, tobacco and intoxicants]]) -> 104.05 | AF3: =AVERAGE(All_India_Index_Upto_April23_CPI_data[[#This Row],[Household goods and services]],All_India_Index_Upto_April23_CPI_data[[#This Row],[Housing]]) -> 102.55 | AG3: =AVERAGE(All_India_Index_Upto_April23_CPI_data[[#This Row],[Personal care and effects]],All_India_Index_Upto_April23_CPI_data[[#This Row],[Health]]) -> 104.2 | AH3: =AVERAGE(All_India_Index_Upto_April23_CPI_data[[#This Row],[Clothing]:[Clothing and footwear]]) -> 105.56667 | AI3: 104 | AJ3: 0 | AN3: 2023 | AQ3: Urban | AR3: 2022 | AS3: May | AT3: 156.7 | AU3: 221.2 | AV3: 164.1 | AW3: 165.4 | AX3: 189.5 | AY3: 174.5 | AZ3: 203.2 | BA3: 164.1 | BB3: 121.2 | BC3: 181.4 | BD3: 158.5 | BE3: 184.9 | BF3: 177.5 | BG3: 174.01538 | BH3: 0 | BI3: 0 | BL3: 2022 | BO3: Urban | BP3: 2021 | BQ3: January | BR3: =DATE(BP3,MONTH(DATEVALUE("1 "&BQ3)),1) -> 44197 | BS3: 148 | BT3: 194.8 | BU3: 178.4 | BV3: 154.4 | BW3: 144.1 | BX3: 152.6 | BY3: 206.8 | BZ3: 162.1 | CA3: 116.3 | CB3: 163 | CC3: 145.9 | CD3: 167.2 | CE3: 163.4 | CF3: 191.8 | CG3: 152.5 | CH3: 137.3 | CI3: 150.2 | CJ3: 157.7 | CK3: 142.9 | CL3: 145.7 | CM3: 154.1 | CN3: 136.9 | CO3: 145.4 | CP3: 156.1 | CQ3: 157.7 | CR3: 147.6 | CS3: 161.30769 | CT3: 168.6 | CU3: 151.7 | CV3: 155.9 | CW3: 146.66667 | CX3: 156 | CY3: -0.0057361377 | CZ3: =VLOOKUP(BR3,'OIL PRICE'!$A$1:$B$27,2,0) -> 54.79
A4: Rural+Urban | B4: 2013 | C4: January | D4: 108.4 | E4: 107.3 | F4: 110 | G4: 104.4 | H4: 105.1 | I4: 103.2 | J4: 102.2 | K4: 106 | L4: 106.2 | M4: 102.7 | N4: 104.9 | O4: 107.3 | P4: 105.6 | Q4: 105.1 | R4: 106.3 | S4: 105.5 | T4: 106.2 | U4: 100.3 | V4: 105.5 | W4: 104.8 | X4: 104 | Y4: 103.2 | Z4: 103.1 | AA4: 103.6 | AB4: 104.5 | AC4: 103.9 | AD4: =AVERAGE(All_India_Index_Upto_April23_CPI_data[[#This Row],[Cereals and products]:[Food and beverages]]) -> 105.63846 | AE4: =AVERAGE(All_India_Index_Upto_April23_CPI_data[[#This Row],[Recreation and amusement]],All_India_Index_Upto_April23_CPI_data[[#This Row],[Pan, tobacco and intoxicants]]) -> 104.1 | AF4: =AVERAGE(All_India_Index_Upto_April23_CPI_data[[#This Row],[Household goods and services]],All_India_Index_Upto_April23_CPI_data[[#This Row],[Housing]]) -> 102.55 | AG4: =AVERAGE(All_India_Index_Upto_April23_CPI_data[[#This Row],[Personal care and effects]],All_India_Index_Upto_April23_CPI_data[[#This Row],[Health]]) -> 104.25 | AH4: =AVERAGE(All_India_Index_Upto_April23_CPI_data[[#This Row],[Clothing]:[Clothing and footwear]]) -> 106 | AI4: 104.6 | AJ4: 0 | AQ4: Rural+Urban | AR4: 2022 | AS4: May | AT4: 154.1 | AU4: 217 | AV4: 162.4 | AW4: 164.9 | AX4: 202.4 | AY4: 171 | AZ4: 174.9 | BA4: 164.7 | BB4: 119.7 | BC4: 184.9 | BD4: 167.1 | BE4: 182.5 | BF4: 173.3 | BG4: 172.22308 | BH4: 0 | BI4: 0 | BL4: 2023 | BO4: Rural+Urban | BP4: 2021 | BQ4: January | BR4: =DATE(BP4,MONTH(DATEVALUE("1 "&BQ4)),1) -> 44197 | BS4: 144.9 | BT4: 190.1 | BU4: 175.3 | BV4: 154.1 | BW4: 150.9 | BX4: 149.6 | BY4: 194.2 | BZ4: 160.4 | CA4: 114.6 | CB4: 164 | CC4: 151.8 | CD4: 165.6 | CE4: 161 | CF4: 186.5 | CG4: 155.5 | CH4: 146.1 | CI4: 154.2 | CJ4: 157.7 | CK4: 147.9 | CL4: 150 | CM4: 159.3 | CN4: 141.9 | CO4: 149.6 | CP4: 159.2 | CQ4: 156.8 | CR4: 151.9 | CS4: 159.73077 | CT4: 168.05 | CU4: 153.85 | CV4: 158.05 | CW4: 151.93333 | CX4: 157.3 | CY4: -0.010069226 | CZ4: =VLOOKUP(BR4,'OIL PRICE'!$A$1:$B$27,2,0) -> 54.79
A5: Rural | B5: 2013 | C5: February | D5: 109.2 | E5: 108.7 | F5: 110.2 | G5: 105.4 | H5: 106.7 | I5: 104 | J5: 102.4 | K5: 105.9 | L5: 105.7 | M5: 103.1 | N5: 105.1 | O5: 107.7 | P5: 106.3 | Q5: 105.6 | R5: 107.1 | S5: 106.3 | T5: 107 | U5: 0 | V5: 106.2 | W5: 105.2 | X5: 104.4 | Y5: 103.9 | Z5: 104 | AA5: 104.1 | AB5: 104.6 | AC5: 104.4 | AD5: =AVERAGE(All_India_Index_Upto_April23_CPI_data[[#This Row],[Cereals and products]:[Food and beverages]]) -> 106.18462 | AE5: =AVERAGE(All_India_Index_Upto_April23_CPI_data[[#This Row],[Recreation and amusement]],All_India_Index_Upto_April23_CPI_data[[#This Row],[Pan, tobacco and intoxicants]]) -> 104.8 | AF5: =AVERAGE(All_India_Index_Upto_April23_CPI_data[[#This Row],[Household goods and services]],All_India_Index_Upto_April23_CPI_data[[#This Row],[Housing]]) -> 52.6 | AG5: =AVERAGE(All_India_Index_Upto_April23_CPI_data[[#This Row],[Personal care and effects]],All_India_Index_Upto_April23_CPI_data[[#This Row],[Health]]) -> 104.5 | AH5: =AVERAGE(All_India_Index_Upto_April23_CPI_data[[#This Row],[Clothing]:[Clothing and footwear]]) -> 106.8 | AI5: 105.8 | AJ5: =(All_India_Index_Upto_April23_CPI_data[[#This Row],[General index]]-AI2)/AI2 -> 0.0066603235 | AQ5: Rural | AR5: 2022 | AS5: June | AT5: 153.8 | AU5: 217.2 | AV5: 169.6 | AW5: 165.4 | AX5: 208.1 | AY5: 165.8 | AZ5: 167.3 | BA5: 164.6 | BB5: 119.1 | BC5: 188.9 | BD5: 174.2 | BE5: 181.9 | BF5: 172.4 | BG5: 172.94615 | BH5: =BG5-BG2 -> 1.6538462 | BI5: =BH5/BG2 -> 0.0096551105 | BO5: Rural | BP5: 2021 | BQ5: February | BR5: =DATE(BP5,MONTH(DATEVALUE("1 "&BQ5)),1) -> 44228 | BS5: 142.8 | BT5: 184 | BU5: 168 | BV5: 154.4 | BW5: 163 | BX5: 147.8 | BY5: 149.7 | BZ5: 158.3 | CA5: 111.8 | CB5: 165 | CC5: 160 | CD5: 165.8 | CE5: 154.7 | CF5: 186.5 | CG5: 159.1 | CH5: 153.9 | CI5: 158.4 | CJ5: 0 | CK5: 154.4 | CL5: 154.8 | CM5: 164.3 | CN5: 150.2 | CO5: 157 | CP5: 163.6 | CQ5: 155.2 | CR5: 157.2 | CS5: 155.79231 | CT5: 171.75 | CU5: 77.4 | CV5: 159.75 | CW5: 157.13333 | CX5: 156.7 | CY5: -0.011356467 | CZ5: =VLOOKUP(BR5,'OIL PRICE'!$A$1:$B$27,2,0) -> 61.22
A6: Urban | B6: 2013 | C6: February | D6: 112.9 | E6: 112.9 | F6: 116.9 | G6: 104 | H6: 103.5 | I6: 103.1 | J6: 104.9 | K6: 104.1 | L6: 103.8 | M6: 102.3 | N6: 106 | O6: 109 | P6: 107.2 | Q6: 106 | R6: 106.6 | S6: 105.5 | T6: 106.4 | U6: 100.4 | V6: 105.7 | W6: 105.2 | X6: 104.7 | Y6: 104.4 | Z6: 103.3 | AA6: 103.7 | AB6: 104.3 | AC6: 104.3 | AD6: =AVERAGE(All_India_Index_Upto_April23_CPI_data[[#This Row],[Cereals and products]:[Food and beverages]]) -> 106.96923 | AE6: =AVERAGE(All_India_Index_Upto_April23_CPI_data[[#This Row],[Recreation and amusement]],All_India_Index_Upto_April23_CPI_data[[#This Row],[Pan, tobacco and intoxicants]]) -> 104.65 | AF6: =AVERAGE(All_India_Index_Upto_April23_CPI_data[[#This Row],[Household goods and services]],All_India_Index_Upto_April23_CPI_data[[#This Row],[Housing]]) -> 102.8 | AG6: =AVERAGE(All_India_Index_Upto_April23_CPI_data[[#This Row],[Personal care and effects]],All_India_Index_Upto_April23_CPI_data[[#This Row],[Health]]) -> 104.5 | AH6: =AVERAGE(All_India_Index_Upto_April23_CPI_data[[#This Row],[Clothing]:[Clothing and footwear]]) -> 106.16667 | AI6: 104.7 | AJ6: =(All_India_Index_Upto_April23_CPI_data[[#This Row],[General index]]-AI3)/AI3 -> 0.0067307692 | AQ6: Urban | AR6: 2022 | AS6: June | AT6: 157.5 | AU6: 223.4 | AV6: 172.8 | AW6: 166.4 | AX6: 188.6 | AY6: 174.1 | AZ6: 211.5 | BA6: 163.6 | BB6: 121.4 | BC6: 183.5 | BD6: 159.1 | BE6: 186.3 | BF6: 179.3 | BG6: 175.96154 | BH6: =BG6-BG3 -> 1.9461538 | BI6: =BH6/BG3 -> 0.011183803 | BO6: Urban | BP6: 2021 | BQ6: February | BR6: =DATE(BP6,MONTH(DATEVALUE("1 "&BQ6)),1) -> 44228 | BS6: 147.6 | BT6: 191.2 | BU6: 169.9 | BV6: 155.1 | BW6: 151.4 | BX6: 154 | BY6: 180.2 | BZ6: 159.8 | CA6: 114.9 | CB6: 162.5 | CC6: 149.2 | CD6: 169.4 | CE6: 160.8 | CF6: 193.3 | CG6: 154.2 | CH6: 138.2 | CI6: 151.8 | CJ6: 159.8 | CK6: 149.1 | CL6: 146.5 | CM6: 156.3 | CN6: 140.5 | CO6: 147.3 | CP6: 156.6 | CQ6: 156.7 | CR6: 149.3 | CS6: 158.92308 | CT6: 170.3 | CU6: 153.15 | CV6: 156.5 | CW6: 148.06667 | CX6: 156.5 | CY6: 0.0032051282 | CZ6: =VLOOKUP(BR6,'OIL PRICE'!$A$1:$B$27,2,0) -> 61.22
A7: Rural+Urban | B7: 2013 | C7: February | D7: 110.4 | E7: 110.2 | F7: 112.8 | G7: 104.9 | H7: 105.5 | I7: 103.6 | J7: 103.2 | K7: 105.3 | L7: 105.1 | M7: 102.8 | N7: 105.5 | O7: 108.3 | P7: 106.6 | Q7: 105.7 | R7: 106.9 | S7: 106 | T7: 106.8 | U7: 100.4 | V7: 106 | W7: 105.2 | X7: 104.5 | Y7: 104.2 | Z7: 103.6 | AA7: 103.9 | AB7: 104.5 | AC7: 104.4 | AD7: =AVERAGE(All_India_Index_Upto_April23_CPI_data[[#This Row],[Cereals and products]:[Food and beverages]]) -> 106.47692 | AE7: =AVERAGE(All_India_Index_Upto_April23_CPI_data[[#This Row],[Recreation and amusement]],All_India_Index_Upto_April23_CPI_data[[#This Row],[Pan, tobacco and intoxicants]]) -> 104.65 | AF7: =AVERAGE(All_India_Index_Upto_April23_CPI_data[[#This Row],[Household goods and services]],All_India_Index_Upto_April23_CPI_data[[#This Row],[Housing]]) -> 102.8 | AG7: =AVERAGE(All_India_Index_Upto_April23_CPI_data[[#This Row],[Personal care and effects]],All_India_Index_Upto_April23_CPI_data[[#This Row],[Health]]) -> 104.5 | AH7: =AVERAGE(All_India_Index_Upto_April23_CPI_data[[#This Row],[Clothing]:[Clothing and footwear]]) -> 106.56667 | AI7: 105.3 | AJ7: =(All_India_Index_Upto_April23_CPI_data[[#This Row],[General index]]-AI4)/AI4 -> 0.0066921606 | AQ7: Rural+Urban | AR7: 2022 | AS7: June | AT7: 155 | AU7: 219.4 | AV7: 170.8 | AW7: 165.8 | AX7: 200.9 | AY7: 169.7 | AZ7: 182.3 | BA7: 164.3 | BB7: 119.9 | BC7: 187.1 | BD7: 167.9 | BE7: 183.9 | BF7: 174.9 | BG7: 173.99231 | BH7: =BG7-BG4 -> 1.7692308 | BI7: =BH7/BG4 -> 0.010272902 | BO7: Rural+Urban | BP7: 2021 | BQ7: February | BR7: =DATE(BP7,MONTH(DATEVALUE("1 "&BQ7)),1) -> 44228 | BS7: 144.3 | BT7: 186.5 | BU7: 168.7 | BV7: 154.7 | BW7: 158.7 | BX7: 150.7 | BY7: 160 | BZ7: 158.8 | CA7: 112.8 | CB7: 164.2 | CC7: 155.5 | CD7: 167.5 | CE7: 156.9 | CF7: 188.3 | CG7: 157.2 | CH7: 147.4 | CI7: 155.8 | CJ7: 159.8 | CK7: 152.4 | CL7: 150.9 | CM7: 161.3 | CN7: 145.1 | CO7: 151.5 | CP7: 159.5 | CQ7: 155.8 | CR7: 153.4 | CS7: 156.86923 | CT7: 169.9 | CU7: 155.35 | CV7: 158.55 | CW7: 153.46667 | CX7: 156.6 | CY7: -0.0044500954 | CZ7: =VLOOKUP(BR7,'OIL PRICE'!$A$1:$B$27,2,0) -> 61.22
A8: Rural | B8: 2013 | C8: March | D8: 110.2 | E8: 108.8 | F8: 109.9 | G8: 105.6 | H8: 106.2 | I8: 105.7 | J8: 101.4 | K8: 105.7 | L8: 105 | M8: 103.3 | N8: 105.6 | O8: 108.2 | P8: 106.6 | Q8: 106.5 | R8: 107.6 | S8: 106.8 | T8: 107.5 | U8: 0 | V8: 106.1 | W8: 105.6 | X8: 104.7 | Y8: 104.6 | Z8: 104 | AA8: 104.3 | AB8: 104.3 | AC8: 104.6 | AD8: =AVERAGE(All_India_Index_Upto_April23_CPI_data[[#This Row],[Cereals and products]:[Food and beverages]]) -> 106.32308 | AE8: =AVERAGE(All_India_Index_Upto_April23_CPI_data[[#This Row],[Recreation and amusement]],All_India_Index_Upto_April23_CPI_data[[#This Row],[Pan, tobacco and intoxicants]]) -> 105.25 | AF8: =AVERAGE(All_India_Index_Upto_April23_CPI_data[[#This Row],[Household goods and services]],All_India_Index_Upto_April23_CPI_data[[#This Row],[Housing]]) -> 52.8 | AG8: =AVERAGE(All_India_Index_Upto_April23_CPI_data[[#This Row],[Personal care and effects]],All_India_Index_Upto_April23_CPI_data[[#This Row],[Health]]) -> 104.5 | AH8: =AVERAGE(All_India_Index_Upto_April23_CPI_data[[#This Row],[Clothing]:[Clothing and footwear]]) -> 107.3 | AI8: 106 | AJ8: =(All_India_Index_Upto_April23_CPI_data[[#This Row],[General index]]-AI5)/AI5 -> 0.0018903592 | AQ8: Rural | AR8: 2022 | AS8: July | AT8: 155.2 | AU8: 210.8 | AV8: 174.3 | AW8: 166.3 | AX8: 202.2 | AY8: 169.6 | AZ8: 168.6 | BA8: 164.4 | BB8: 119.2 | BC8: 191.8 | BD8: 174.5 | BE8: 183.1 | BF8: 172.5 | BG8: 173.26923 | BH8: =BG8-BG5 -> 0.32307692 | BI8: =BH8/BG5 -> 0.0018680781 | BO8: Rural | BP8: 2021 | BQ8: March | BR8: =DATE(BP8,MONTH(DATEVALUE("1 "&BQ8)),1) -> 44256 | BS8: 142.5 | BT8: 189.4 | BU8: 163.2 | BV8: 154.5 | BW8: 168.2 | BX8: 150.5 | BY8: 141 | BZ8: 159.2 | CA8: 111.7 | CB8: 164 | CC8: 160.6 | CD8: 166.4 | CE8: 154.5 | CF8: 186.1 | CG8: 159.6 | CH8: 154.4 | CI8: 158.9 | CJ8: 0 | CK8: 156 | CL8: 154.8 | CM8: 164.6 | CN8: 151.3 | CO8: 157.8 | CP8: 163.8 | CQ8: 153.1 | CR8: 157.3 | CS8: 155.82308 | CT8: 171.95 | CU8: 77.4 | CV8: 158.85 | CW8: 157.63333 | CX8: 156.7 | CY8: 0 | CZ8: =VLOOKUP(BR8,'OIL PRICE'!$A$1:$B$27,2,0) -> 64.73
A9: Urban | B9: 2013 | C9: March | D9: 113.9 | E9: 111.4 | F9: 113.2 | G9: 104.3 | H9: 102.7 | I9: 104.9 | J9: 103.8 | K9: 103.5 | L9: 102.6 | M9: 102.4 | N9: 107 | O9: 109.8 | P9: 107.3 | Q9: 106.8 | R9: 107.2 | S9: 106 | T9: 107 | U9: 100.4 | V9: 106 | W9: 105.7 | X9: 105.2 | Y9: 105.5 | Z9: 103.5 | AA9: 103.8 | AB9: 104.2 | AC9: 104.9 | AD9: =AVERAGE(All_India_Index_Upto_April23_CPI_data[[#This Row],[Cereals and products]:[Food and beverages]]) -> 106.67692 | AE9: =AVERAGE(All_India_Index_Upto_April23_CPI_data[[#This Row],[Recreation and amusement]],All_India_Index_Upto_April23_CPI_data[[#This Row],[Pan, tobacco and intoxicants]]) -> 105.15 | AF9: =AVERAGE(All_India_Index_Upto_April23_CPI_data[[#This Row],[Household goods and services]],All_India_Index_Upto_April23_CPI_data[[#This Row],[Housing]]) -> 103.05 | AG9: =AVERAGE(All_India_Index_Upto_April23_CPI_data[[#This Row],[Personal care and effects]],All_India_Index_Upto_April23_CPI_data[[#This Row],[Health]]) -> 104.7 | AH9: =AVERAGE(All_India_Index_Upto_April23_CPI_data[[#This Row],[Clothing]:[Clothing and footwear]]) -> 106.73333 | AI9: 105 | AJ9: =(All_India_Index_Upto_April23_CPI_data[[#This Row],[General index]]-AI6)/AI6 -> 0.0028653295 | AQ9: Urban | AR9: 2022 | AS9: July | AT9: 159.3 | AU9: 217.1 | AV9: 176.6 | AW9: 167.1 | AX9: 184.8 | AY9: 179.5 | AZ9: 208.5 | BA9: 164 | BB9: 121.5 | BC9: 186.3 | BD9: 159.8 | BE9: 187.7 | BF9: 179.4 | BG9: 176.27692 | BH9: =BG9-BG6 -> 0.31538462 | BI9: =BH9/BG6 -> 0.0017923497 | BO9: Urban | BP9: 2021 | BQ9: March | BR9: =DATE(BP9,MONTH(DATEVALUE("1 "&BQ9)),1) -> 44256 | BS9: 147.5 | BT9: 197.5 | BU9: 164.7 | BV9: 155.6 | BW9: 156.4 | BX9: 157.3 | BY9: 166.1 | BZ9: 161.1 | CA9: 114.3 | CB9: 162.6 | CC9: 150.7 | CD9: 170.3 | CE9: 160.4 | CF9: 193.5 | CG9: 155.1 | CH9: 138.7 | CI9: 152.6 | CJ9: 159.9 | CK9: 154.8 | CL9: 147.2 | CM9: 156.9 | CN9: 141.7 | CO9: 148.6 | CP9: 157.6 | CQ9: 154.9 | CR9: 150 | CS9: 158.80769 | CT9: 171.05 | CU9: 153.55 | CV9: 155.9 | CW9: 148.8 | CX9: 156.9 | CY9: 0.0025559105 | CZ9: =VLOOKUP(BR9,'OIL PRICE'!$A$1:$B$27,2,0) -> 64.73
A10: Rural+Urban | B10: 2013 | C10: March | D10: 111.4 | E10: 109.7 | F10: 111.2 | G10: 105.1 | H10: 104.9 | I10: 105.3 | J10: 102.2 | K10: 105 | L10: 104.2 | M10: 103 | N10: 106.2 | O10: 108.9 | P10: 106.9 | Q10: 106.6 | R10: 107.4 | S10: 106.5 | T10: 107.3 | U10: 100.4 | V10: 106.1 | W10: 105.6 | X10: 104.9 | Y10: 105.1 | Z10: 103.7 | AA10: 104 | AB10: 104.3 | AC10: 104.7 | AD10: =AVERAGE(All_India_Index_Upto_April23_CPI_data[[#This Row],[Cereals and products]:[Food and beverages]]) -> 106.46154 | AE10: =AVERAGE(All_India_Index_Upto_April23_CPI_data[[#This Row],[Recreation and amusement]],All_India_Index_Upto_April23_CPI_data[[#This Row],[Pan, tobacco and intoxicants]]) -> 105.15 | AF10: =AVERAGE(All_India_Index_Upto_April23_CPI_data[[#This Row],[Household goods and services]],All_India_Index_Upto_April23_CPI_data[[#This Row],[Housing]]) -> 103 | AG10: =AVERAGE(All_India_Index_Upto_April23_CPI_data[[#This Row],[Personal care and effects]],All_India_Index_Upto_April23_CPI_data[[#This Row],[Health]]) -> 104.6 | AH10: =AVERAGE(All_India_Index_Upto_April23_CPI_data[[#This Row],[Clothing]:[Clothing and footwear]]) -> 107.06667 | AI10: 105.5 | AJ10: =(All_India_Index_Upto_April23_CPI_data[[#This Row],[General index]]-AI7)/AI7 -> 0.0018993352 | AQ10: Rural+Urban | AR10: 2022 | AS10: July | AT10: 156.5 | AU10: 213 | AV10: 175.2 | AW10: 166.6 | AX10: 195.8 | AY10: 174.2 | AZ10: 182.1 | BA10: 164.3 | BB10: 120 | BC10: 190 | BD10: 168.4 | BE10: 185.2 | BF10: 175 | BG10: 174.33077 | BH10: =BG10-BG7 -> 0.33846154 | BI10: =BH10/BG7 -> 0.0019452673 | BO10: Rural+Urban | BP10: 2021 | BQ10: March | BR10: =DATE(BP10,MONTH(DATEVALUE("1 "&BQ10)),1) -> 44256 | BS10: 144.1 | BT10: 192.2 | BU10: 163.8 | BV10: 154.9 | BW10: 163.9 | BX10: 153.7 | BY10: 149.5 | BZ10: 159.8 | CA10: 112.6 | CB10: 163.5 | CC10: 156.5 | CD10: 168.2 | CE10: 156.7 | CF10: 188.1 | CG10: 157.8 | CH10: 147.9 | CI10: 156.4 | CJ10: 159.9 | CK10: 155.5 | CL10: 151.2 | CM10: 161.7 | CN10: 146.2 | CO10: 152.6 | CP10: 160.2 | CQ10: 153.8 | CR10: 153.8 | CS10: 156.87692 | CT10: 170.35 | CU10: 155.55 | CV10: 157.75 | CW10: 154.03333 | CX10: 156.8 | CY10: 0.0012771392 | CZ10: =VLOOKUP(BR10,'OIL PRICE'!$A$1:$B$27,2,0) -> 64.73
A11: Rural | B11: 2013 | C11: April | D11: 110.2 | E11: 109.5 | F11: 106.9 | G11: 106.3 | H11: 105.7 | I11: 108.3 | J11: 103.4 | K11: 105.7 | L11: 104.2 | M11: 103.2 | N11: 106.5 | O11: 108.8 | P11: 107.1 | Q11: 107.1 | R11: 108.1 | S11: 107.4 | T11: 108 | U11: 0 | V11: 106.5 | W11: 106.1 | X11: 105.1 | Y11: 104.4 | Z11: 104.5 | AA11: 104.8 | AB11: 102.7 | AC11: 104.6 | AD11: =AVERAGE(All_India_Index_Upto_April23_CPI_data[[#This Row],[Cereals and products]:[Food and beverages]]) -> 106.6 | AE11: =AVERAGE(All_India_Index_Upto_April23_CPI_data[[#This Row],[Recreation and amusement]],All_India_Index_Upto_April23_CPI_data[[#This Row],[Pan, tobacco and intoxicants]]) -> 105.8 | AF11: =AVERAGE(All_India_Index_Upto_April23_CPI_data[[#This Row],[Household goods and services]],All_India_Index_Upto_April23_CPI_data[[#This Row],[Housing]]) -> 53.05 | AG11: =AVERAGE(All_India_Index_Upto_April23_CPI_data[[#This Row],[Personal care and effects]],All_India_Index_Upto_April23_CPI_data[[#This Row],[Health]]) -> 103.9 | AH11: =AVERAGE(All_India_Index_Upto_April23_CPI_data[[#This Row],[Clothing]:[Clothing and footwear]]) -> 107.83333 | AI11: 106.4 | AJ11: =(All_India_Index_Upto_April23_CPI_data[[#This Row],[General index]]-AI8)/AI8 -> 0.0037735849 | AQ11: Rural | AR11: 2022 | AS11: August | AT11: 159.5 | AU11: 204.1 | AV11: 168.3 | AW11: 167.9 | AX11: 198.1 | AY11: 169.2 | AZ11: 173.1 | BA11: 167.1 | BB11: 120.2 | BC11: 195.6 | BD11: 174.8 | BE11: 184 | BF11: 173.9 | BG11: 173.52308 | BH11: =BG11-BG8 -> 0.25384615 | BI11: =BH11/BG8 -> 0.0014650388 | BO11: Rural | BP11: 2021 | BQ11: April | BR11: =DATE(BP11,MONTH(DATEVALUE("1 "&BQ11)),1) -> 44287 | BS11: 142.7 | BT11: 195.5 | BU11: 163.4 | BV11: 155 | BW11: 175.2 | BX11: 160.6 | BY11: 135.1 | BZ11: 161.1 | CA11: 112.2 | CB11: 164.4 | CC11: 161.9 | CD11: 166.8 | CE11: 155.6 | CF11: 186.8 | CG11: 160.7 | CH11: 155.1 | CI11: 159.9 | CJ11: 0 | CK11: 156 | CL11: 155.5 | CM11: 165.3 | CN11: 151.7 | CO11: 158.6 | CP11: 164.1 | CQ11: 154.6 | CR11: 158 | CS11: 157.65385 | CT11: 172.7 | CU11: 77.75 | CV11: 159.95 | CW11: 158.56667 | CX11: 157.6 | CY11: 0.0057434588 | CZ11: =VLOOKUP(BR11,'OIL PRICE'!$A$1:$B$27,2,0) -> 63.4
A12: Urban | B12: 2013 | C12: April | D12: 114.6 | E12: 113.4 | F12: 106 | G12: 104.7 | H12: 102.1 | I12: 109.5 | J12: 109.7 | K12: 104.6 | L12: 102 | M12: 103.5 | N12: 108.2 | O12: 110.6 | P12: 108.8 | Q12: 108.5 | R12: 107.9 | S12: 106.4 | T12: 107.7 | U12: 100.5 | V12: 106.4 | W12: 106.5 | X12: 105.7 | Y12: 105 | Z12: 104 | AA12: 105.2 | AB12: 103.2 | AC12: 105.1 | AD12: =AVERAGE(All_India_Index_Upto_April23_CPI_data[[#This Row],[Cereals and products]:[Food and beverages]]) -> 107.51538 | AE12: =AVERAGE(All_India_Index_Upto_April23_CPI_data[[#This Row],[Recreation and amusement]],All_India_Index_Upto_April23_CPI_data[[#This Row],[Pan, tobacco and intoxicants]]) -> 106.25 | AF12: =AVERAGE(All_India_Index_Upto_April23_CPI_data[[#This Row],[Household goods and services]],All_India_Index_Upto_April23_CPI_data[[#This Row],[Housing]]) -> 103.5 | AG12: =AVERAGE(All_India_Index_Upto_April23_CPI_data[[#This Row],[Personal care and effects]],All_India_Index_Upto_April23_CPI_data[[#This Row],[Health]]) -> 104.45 | AH12: =AVERAGE(All_India_Index_Upto_April23_CPI_data[[#This Row],[Clothing]:[Clothing and footwear]]) -> 107.33333 | AI12: 105.7 | AJ12: =(All_India_Index_Upto_April23_CPI_data[[#This Row],[General index]]-AI9)/AI9 -> 0.0066666667 | AQ12: Urban | AR12: 2022 | AS12: August | AT12: 162.1 | AU12: 210.9 | AV12: 170.6 | AW12: 168.4 | AX12: 182.5 | AY12: 177.1 | AZ12: 213.1 | BA12: 167.3 | BB12: 122.2 | BC12: 189.7 | BD12: 160.5 | BE12: 188.9 | BF12: 180.4 | BG12: 176.43846 | BH12: =BG12-BG9 -> 0.16153846 | BI12: =BH12/BG9 -> 0.00091639029 | BO12: Urban | BP12: 2021 | BQ12: April | BR12: =DATE(BP12,MONTH(DATEVALUE("1 "&BQ12)),1) -> 44287 | BS12: 147.6 | BT12: 202.5 | BU12: 166.4 | BV12: 156 | BW12: 161.4 | BX12: 168.8 | BY12: 161.6 | BZ12: 162.8 | CA12: 114.8 | CB12: 162.8 | CC12: 151.5 | CD12: 171.4 | CE12: 162 | CF12: 194.4 | CG12: 155.9 | CH12: 139.3 | CI12: 153.4 | CJ12: 161.4 | CK12: 154.9 | CL12: 147.6 | CM12: 157.5 | CN12: 142.1 | CO12: 149.1 | CP12: 157.6 | CQ12: 156.6 | CR12: 150.5 | CS12: 160.73846 | CT12: 171.75 | CU12: 154.5 | CV12: 157.05 | CW12: 149.53333 | CX12: 158 | CY12: 0.0070108349 | CZ12: =VLOOKUP(BR12,'OIL PRICE'!$A$1:$B$27,2,0) -> 63.4
A13: Rural+Urban | B13: 2013 | C13: April | D13: 111.6 | E13: 110.9 | F13: 106.6 | G13: 105.7 | H13: 104.4 | I13: 108.9 | J13: 105.5 | K13: 105.3 | L13: 103.5 | M13: 103.3 | N13: 107.2 | O13: 109.6 | P13: 107.7 | Q13: 107.5 | R13: 108 | S13: 107 | T13: 107.9 | U13: 100.5 | V13: 106.5 | W13: 106.3 | X13: 105.3 | Y13: 104.7 | Z13: 104.2 | AA13: 105 | AB13: 102.9 | AC13: 104.8 | AD13: =AVERAGE(All_India_Index_Upto_April23_CPI_data[[#This Row],[Cereals and products]:[Food and beverages]]) -> 106.93846 | AE13: =AVERAGE(All_India_Index_Upto_April23_CPI_data[[#This Row],[Recreation and amusement]],All_India_Index_Upto_April23_CPI_data[[#This Row],[Pan, tobacco and intoxicants]]) -> 105.85 | AF13: =AVERAGE(All_India_Index_Upto_April23_CPI_data[[#This Row],[Household goods and services]],All_India_Index_Upto_April23_CPI_data[[#This Row],[Housing]]) -> 103.4 | AG13: =AVERAGE(All_India_Index_Upto_April23_CPI_data[[#This Row],[Personal care and effects]],All_India_Index_Upto_April23_CPI_data[[#This Row],[Health]]) -> 104.1 | AH13: =AVERAGE(All_India_Index_Upto_April23_CPI_data[[#This Row],[Clothing]:[Clothing and footwear]]) -> 107.63333 | AI13: 106.1 | AJ13: =(All_India_Index_Upto_April23_CPI_data[[#This Row],[General index]]-AI10)/AI10 -> 0.0056872038 | AQ13: Rural+Urban | AR13: 2022 | AS13: August | AT13: 160.3 | AU13: 206.5 | AV13: 169.2 | AW13: 168.1 | AX13: 192.4 | AY13: 172.9 | AZ13: 186.7 | BA13: 167.2 | BB13: 120.9 | BC13: 193.6 | BD13: 168.8 | BE13: 186.3 | BF13: 176.3 | BG13: 174.55385 | BH13: =BG13-BG10 -> 0.22307692 | BI13: =BH13/BG10 -> 0.0012796188 | BO13: Rural+Urban | BP13: 2021 | BQ13: April | BR13: =DATE(BP13,MONTH(DATEVALUE("1 "&BQ13)),1) -> 44287 | BS13: 144.3 | BT13: 198 | BU13: 164.6 | BV13: 155.4 | BW13: 170.1 | BX13: 164.4 | BY13: 144.1 | BZ13: 161.7 | CA13: 113.1 | CB13: 163.9 | CC13: 157.6 | CD13: 168.9 | CE13: 158 | CF13: 188.8 | CG13: 158.8 | CH13: 148.5 | CI13: 157.3 | CJ13: 161.4 | CK13: 155.6 | CL13: 151.8 | CM13: 162.3 | CN13: 146.6 | CO13: 153.2 | CP13: 160.3 | CQ13: 155.4 | CR13: 154.4 | CS13: 158.77692 | CT13: 171 | CU13: 156.6 | CV13: 158.85 | CW13: 154.86667 | CX13: 157.8 | CY13: 0.006377551 | CZ13: =VLOOKUP(BR13,'OIL PRICE'!$A$1:$B$27,2,0) -> 63.4
A14: Rural | B14: 2013 | C14: May | D14: 110.9 | E14: 109.8 | F14: 105.9 | G14: 107.5 | H14: 105.3 | I14: 108.1 | J14: 107.3 | K14: 106.1 | L14: 103.7 | M14: 104 | N14: 107.4 | O14: 109.9 | P14: 108.1 | Q14: 108.1 | R14: 108.8 | S14: 107.9 | T14: 108.6 | U14: 0 | V14: 107.5 | W14: 106.8 | X14: 105.7 | Y14: 104.1 | Z14: 105 | AA14: 105.5 | AB14: 102.1 | AC14: 104.8 | AD14: =AVERAGE(All_India_Index_Upto_April23_CPI_data[[#This Row],[Cereals and products]:[Food and beverages]]) -> 107.23077 | AE14: =AVERAGE(All_India_Index_Upto_April23_CPI_data[[#This Row],[Recreation and amusement]],All_India_Index_Upto_April23_CPI_data[[#This Row],[Pan, tobacco and intoxicants]]) -> 106.55 | AF14: =AVERAGE(All_India_Index_Upto_April23_CPI_data[[#This Row],[Household goods and services]],All_India_Index_Upto_April23_CPI_data[[#This Row],[Housing]]) -> 53.4 | AG14: =AVERAGE(All_India_Index_Upto_April23_CPI_data[[#This Row],[Personal care and effects]],All_India_Index_Upto_April23_CPI_data[[#This Row],[Health]]) -> 103.9 | AH14: =AVERAGE(All_India_Index_Upto_April23_CPI_data[[#This Row],[Clothing]:[Clothing and footwear]]) -> 108.43333 | AI14: 107.2 | AJ14: =(All_India_Index_Upto_April23_CPI_data[[#This Row],[General index]]-AI11)/AI11 -> 0.007518797 | AQ14: Rural | AR14: 2022 | AS14: September | AT14: 162.9 | AU14: 206.7 | AV14: 169 | AW14: 169.5 | AX14: 194.1 | AY14: 164.1 | AZ14: 176.9 | BA14: 169 | BB14: 120.8 | BC14: 199.1 | BD14: 175.4 | BE14: 184.8 | BF14: 175.5 | BG14: 174.44615 | BH14: =BG14-BG11 -> 0.92307692 | BI14: =BH14/BG11 -> 0.0053196205 | BO14: Rural | BP14: 2021 | BQ14: May | BR14: =DATE(BP14,MONTH(DATEVALUE("1 "&BQ14)),1) -> 44317 | BS14: 145.1 | BT14: 198.5 | BU14: 168.6 | BV14: 155.8 | BW14: 184.4 | BX14: 162.3 | BY14: 138.4 | BZ14: 165.1 | CA14: 114.3 | CB14: 169.7 | CC14: 164.6 | CD14: 169.8 | CE14: 158.7 | CF14: 189.6 | CG14: 165.3 | CH14: 160.6 | CI14: 164.5 | CJ14: 0 | CK14: 161.7 | CL14: 158.8 | CM14: 169.1 | CN14: 153.2 | CO14: 160 | CP14: 167.6 | CQ14: 159.3 | CR14: 161.1 | CS14: 161.17692 | CT14: 174.8 | CU14: 79.4 | CV14: 164.2 | CW14: 163.46667 | CX14: 161.1 | CY14: 0.022208122 | CZ14: =VLOOKUP(BR14,'OIL PRICE'!$A$1:$B$27,2,0) -> 66.95
A15: Urban | B15: 2013 | C15: May | D15: 115.4 | E15: 114.2 | F15: 102.7 | G15: 105.5 | H15: 101.5 | I15: 110.6 | J15: 123.7 | K15: 105.2 | L15: 101.9 | M15: 105 | N15: 109.1 | O15: 111.3 | P15: 111.1 | Q15: 109.8 | R15: 108.5 | S15: 106.7 | T15: 108.3 | U15: 100.5 | V15: 107.2 | W15: 107.1 | X15: 106.2 | Y15: 103.9 | Z15: 104.6 | AA15: 105.7 | AB15: 102.6 | AC15: 104.9 | AD15: =AVERAGE(All_India_Index_Upto_April23_CPI_data[[#This Row],[Cereals and products]:[Food and beverages]]) -> 109.01538 | AE15: =AVERAGE(All_India_Index_Upto_April23_CPI_data[[#This Row],[Recreation and amusement]],All_India_Index_Upto_April23_CPI_data[[#This Row],[Pan, tobacco and intoxicants]]) -> 107.2 | AF15: =AVERAGE(All_India_Index_Upto_April23_CPI_data[[#This Row],[Household goods and services]],All_India_Index_Upto_April23_CPI_data[[#This Row],[Housing]]) -> 103.8 | AG15: =AVERAGE(All_India_Index_Upto_April23_CPI_data[[#This Row],[Personal care and effects]],All_India_Index_Upto_April23_CPI_data[[#This Row],[Health]]) -> 104.4 | AH15: =AVERAGE(All_India_Index_Upto_April23_CPI_data[[#This Row],[Clothing]:[Clothing and footwear]]) -> 107.83333 | AI15: 106.6 | AJ15: =(All_India_Index_Upto_April23_CPI_data[[#This Row],[General index]]-AI12)/AI12 -> 0.0085146641 | AQ15: Urban | AR15: 2022 | AS15: September | AT15: 164.9 | AU15: 213.7 | AV15: 170.9 | AW15: 170.1 | AX15: 179.3 | AY15: 167.5 | AZ15: 220.8 | BA15: 169.2 | BB15: 123.1 | BC15: 193.6 | BD15: 161.1 | BE15: 190.4 | BF15: 181.8 | BG15: 177.41538 | BH15: =BG15-BG12 -> 0.97692308 | BI15: =BH15/BG12 -> 0.0055369054 | BO15: Urban | BP15: 2021 | BQ15: May | BR15: =DATE(BP15,MONTH(DATEVALUE("1 "&BQ15)),1) -> 44317 | BS15: 148.8 | BT15: 204.3 | BU15: 173 | BV15: 156.5 | BW15: 168.8 | BX15: 172.5 | BY15: 166.5 | BZ15: 165.9 | CA15: 115.9 | CB15: 165.2 | CC15: 152 | CD15: 171.1 | CE15: 164.2 | CF15: 198.2 | CG15: 156.5 | CH15: 140.2 | CI15: 154.1 | CJ15: 161.6 | CK15: 155.5 | CL15: 150.1 | CM15: 160.4 | CN15: 145 | CO15: 152.6 | CP15: 156.6 | CQ15: 157.5 | CR15: 152.3 | CS15: 163.43846 | CT15: 175.4 | CU15: 155.85 | CV15: 158.95 | CW15: 150.26667 | CX15: 159.5 | CY15: 0.0094936709 | CZ15: =VLOOKUP(BR15,'OIL PRICE'!$A$1:$B$27,2,0) -> 66.95
A16: Rural+Urban | B16: 2013 | C16: May | D16: 112.3 | E16: 111.3 | F16: 104.7 | G16: 106.8 | H16: 103.9 | I16: 109.3 | J16: 112.9 | K16: 105.8 | L16: 103.1 | M16: 104.3 | N16: 108.1 | O16: 110.5 | P16: 109.2 | Q16: 108.6 | R16: 108.7 | S16: 107.4 | T16: 108.5 | U16: 100.5 | V16: 107.4 | W16: 106.9 | X16: 105.9 | Y16: 104 | Z16: 104.8 | AA16: 105.6 | AB16: 102.3 | AC16: 104.8 | AD16: =AVERAGE(All_India_Index_Upto_April23_CPI_data[[#This Row],[Cereals and products]:[Food and beverages]]) -> 107.86154 | AE16: =AVERAGE(All_India_Index_Upto_April23_CPI_data[[#This Row],[Recreation and amusement]],All_India_Index_Upto_April23_CPI_data[[#This Row],[Pan, tobacco and intoxicants]]) -> 106.7 | AF16: =AVERAGE(All_India_Index_Upto_April23_CPI_data[[#This Row],[Household goods and services]],All_India_Index_Upto_April23_CPI_data[[#This Row],[Housing]]) -> 103.7 | AG16: =AVERAGE(All_India_Index_Upto_April23_CPI_data[[#This Row],[Personal care and effects]],All_India_Index_Upto_April23_CPI_data[[#This Row],[Health]]) -> 104.1 | AH16: =AVERAGE(All_India_Index_Upto_April23_CPI_data[[#This Row],[Clothing]:[Clothing and footwear]]) -> 108.2 | AI16: 106.9 | AJ16: =(All_India_Index_Upto_April23_CPI_data[[#This Row],[General index]]-AI13)/AI13 -> 0.0075400566 | AQ16: Rural+Urban | AR16: 2022 | AS16: September | AT16: 163.5 | AU16: 209.2 | AV16: 169.7 | AW16: 169.7 | AX16: 188.7 | AY16: 165.7 | AZ16: 191.8 | BA16: 169.1 | BB16: 121.6 | BC16: 197.3 | BD16: 169.4 | BE16: 187.4 | BF16: 177.8 | BG16: 175.45385 | BH16: =BG16-BG13 -> 0.9 | BI16: =BH16/BG13 -> 0.0051560021 | BO16: Rural+Urban | BP16: 2021 | BQ16: May | BR16: =DATE(BP16,MONTH(DATEVALUE("1 "&BQ16)),1) -> 44317 | BS16: 146.3 | BT16: 200.5 | BU16: 170.3 | BV16: 156.1 | BW16: 178.7 | BX16: 167.1 | BY16: 147.9 | BZ16: 165.4 | CA16: 114.8 | CB16: 168.2 | CC16: 159.3 | CD16: 170.4 | CE16: 160.7 | CF16: 191.9 | CG16: 161.8 | CH16: 152.1 | CI16: 160.4 | CJ16: 161.6 | CK16: 159.4 | CL16: 154.7 | CM16: 165.8 | CN16: 148.9 | CO16: 155.8 | CP16: 161.2 | CQ16: 158.6 | CR16: 156.8 | CS16: 161.97692 | CT16: 173.85 | CU16: 158.15 | CV16: 162.2 | CW16: 158.1 | CX16: 160.4 | CY16: 0.016476553 | CZ16: =VLOOKUP(BR16,'OIL PRICE'!$A$1:$B$27,2,0) -> 66.95
... A40: Rural+Urban | B40: 2014 | C40: January | D40: 119.6 | E40: 118.8 | F40: 124.1 | G40: 114.1 | H40: 106.8 | I40: 113.9 | J40: 122.2 | K40: 108.9 | L40: 100.2 | M40: 111 | N40: 112.3 | O40: 118.1 | P40: 115.8 | Q40: 114.5 | R40: 115.8 | S40: 113.2 | T40: 115.4 | U40: 111.6 | V40: 112.2 | W40: 112.3 | X40: 110.3 | Y40: 110.7 | Z40: 109.7 | AA40: 111.6 | AB40: 108.2 | AC40: 110.6 | AD40: =AVERAGE(All_India_Index_Upto_April23_CPI_data[[#This Row],[Cereals and products]:[Food and beverages]]) -> 114.29231 | AE40: =AVERAGE(All_India_Index_Upto_April23_CPI_data[[#This Row],[Recreation and amusement]],All_India_Index_Upto_April23_CPI_data[[#This Row],[Pan, tobacco and intoxicants]]) -> 112.1 | AF40: =AVERAGE(All_India_Index_Upto_April23_CPI_data[[#This Row],[Household goods and services]],All_India_Index_Upto_April23_CPI_data[[#This Row],[Housing]]) -> 111.95 | AG40: =AVERAGE(All_India_Index_Upto_April23_CPI_data[[#This Row],[Personal care and effects]],All_India_Index_Upto_April23_CPI_data[[#This Row],[Health]]) -> 109.25 | AH40: =AVERAGE(All_India_Index_Upto_April23_CPI_data[[#This Row],[Clothing]:[Clothing and footwear]]) -> 114.8 | AI40: 113.6 | AJ40: =(All_India_Index_Upto_April23_CPI_data[[#This Row],[General index]]-AI37)/AI37 -> -0.007860262 | AQ40: Rural+Urban | AR40: 2023 | AS40: May | AT40: 173.7 | AU40: 214.3 | AV40: 173.2 | AW40: 179.5 | AX40: 170 | AY40: 172.2 | AZ40: 161 | BA40: 175.6 | BB40: 122.7 | BC40: 218 | BD40: 173.4 | BE40: 194.2 | BF40: 179.1 | BG40: 177.45385 | BH40: =BG40-BG37 -> 1.3307692 | BI40: =BH40/BG37 -> 0.007555905 | BO40: Rural+Urban | BP40: 2022 | BQ40: January | BR40: =DATE(BP40,MONTH(DATEVALUE("1 "&BQ40)),1) -> 44562 | BS40: 149.5 | BT40: 198.7 | BU40: 178.8 | BV40: 160.5 | BW40: 184.7 | BX40: 153.7 | BY40: 174.3 | BZ40: 163.9 | CA40: 120 | CB40: 172.1 | CC40: 164.3 | CD40: 177.3 | CE40: 166.4 | CF40: 192.2 | CG40: 169.9 | CH40: 160.7 | CI40: 168.5 | CJ40: 164.5 | CK40: 164.2 | CL40: 161.1 | CM40: 171.4 | CN40: 156.5 | CO40: 161.2 | CP40: 164.7 | CQ40: 163 | CR40: 162.7 | CS40: 166.47692 | CT40: 176.7 | CU40: 162.8 | CV40: 167.2 | CW40: 166.36667 | CX40: 165.7 | CY40: -0.0030084236 | CZ40: =VLOOKUP(BR40,'OIL PRICE'!$A$1:$B$27,2,0) -> 84.67
A41: Rural | B41: 2014 | C41: February | D41: 119.4 | E41: 117.7 | F41: 121.2 | G41: 115 | H41: 109 | I41: 116.6 | J41: 116 | K41: 109.8 | L41: 101.1 | M41: 110.4 | N41: 112.9 | O41: 117.8 | P41: 115.3 | Q41: 114.2 | R41: 117.1 | S41: 114.5 | T41: 116.7 | U41: 0 | V41: 113.2 | W41: 112.9 | X41: 110.9 | Y41: 110.8 | Z41: 109.9 | AA41: 112 | AB41: 108.7 | AC41: 110.9 | AD41: =AVERAGE(All_India_Index_Upto_April23_CPI_data[[#This Row],[Cereals and products]:[Food and beverages]]) -> 114.01538 | AE41: =AVERAGE(All_India_Index_Upto_April23_CPI_data[[#This Row],[Recreation and amusement]],All_India_Index_Upto_April23_CPI_data[[#This Row],[Pan, tobacco and intoxicants]]) -> 112.05 | AF41: =AVERAGE(All_India_Index_Upto_April23_CPI_data[[#This Row],[Household goods and services]],All_India_Index_Upto_April23_CPI_data[[#This Row],[Housing]]) -> 56.45 | AG41: =AVERAGE(All_India_Index_Upto_April23_CPI_data[[#This Row],[Personal care and effects]],All_India_Index_Upto_April23_CPI_data[[#This Row],[Health]]) -> 109.8 | AH41: =AVERAGE(All_India_Index_Upto_April23_CPI_data[[#This Row],[Clothing]:[Clothing and footwear]]) -> 116.1 | AI41: 114 | AJ41: =(All_India_Index_Upto_April23_CPI_data[[#This Row],[General index]]-AI38)/AI38 -> -0.0017513135 | BO41: Rural | BP41: 2022 | BQ41: February | BR41: =DATE(BP41,MONTH(DATEVALUE("1 "&BQ41)),1) -> 44593 | BS41: 148.8 | BT41: 198.1 | BU41: 175.5 | BV41: 160.7 | BW41: 192.6 | BX41: 151.4 | BY41: 155.2 | BZ41: 163.9 | CA41: 118.1 | CB41: 175.4 | CC41: 170.5 | CD41: 176.3 | CE41: 163.9 | CF41: 191.5 | CG41: 174.1 | CH41: 171 | CI41: 173.7 | CJ41: 0 | CK41: 167.4 | CL41: 165.7 | CM41: 175.3 | CN41: 161.2 | CO41: 165.5 | CP41: 170.3 | CQ41: 164.5 | CR41: 167.3 | CS41: 165.41538 | CT41: 178.5 | CU41: 82.85 | CV41: 169.9 | CW41: 172.93333 | CX41: 166.7 | CY41: 0.0018028846 | CZ41: =VLOOKUP(BR41,'OIL PRICE'!$A$1:$B$27,2,0) -> 94.07
A42: Urban | B42: 2014 | C42: February | D42: 121.9 | E42: 122 | F42: 124.5 | G42: 115.2 | H42: 102.5 | I42: 114.1 | J42: 111.5 | K42: 108.2 | L42: 95.4 | M42: 113.5 | N42: 112.1 | O42: 119.9 | P42: 115.2 | Q42: 116.2 | R42: 115.3 | S42: 111.7 | T42: 114.7 | U42: 112.5 | V42: 111.1 | W42: 112.6 | X42: 110.4 | Y42: 111.3 | Z42: 110.3 | AA42: 111.6 | AB42: 108.7 | AC42: 111 | AD42: =AVERAGE(All_India_Index_Upto_April23_CPI_data[[#This Row],[Cereals and products]:[Food and beverages]]) -> 113.53846 | AE42: =AVERAGE(All_India_Index_Upto_April23_CPI_data[[#This Row],[Recreation and amusement]],All_India_Index_Upto_April23_CPI_data[[#This Row],[Pan, tobacco and intoxicants]]) -> 113.25 | AF42: =AVERAGE(All_India_Index_Upto_April23_CPI_data[[#This Row],[Household goods and services]],All_India_Index_Upto_April23_CPI_data[[#This Row],[Housing]]) -> 112.55 | AG42: =AVERAGE(All_India_Index_Upto_April23_CPI_data[[#This Row],[Personal care and effects]],All_India_Index_Upto_April23_CPI_data[[#This Row],[Health]]) -> 109.55 | AH42: =AVERAGE(All_India_Index_Upto_April23_CPI_data[[#This Row],[Clothing]:[Clothing and footwear]]) -> 113.9 | AI42: 113.1 | AJ42: =(All_India_Index_Upto_April23_CPI_data[[#This Row],[General index]]-AI39)/AI39 -> 0.0017714792 | BO42: Urban | BP42: 2022 | BQ42: February | BR42: =DATE(BP42,MONTH(DATEVALUE("1 "&BQ42)),1) -> 44593 | BS42: 152.5 | BT42: 205.2 | BU42: 176.4 | BV42: 160.6 | BW42: 171.5 | BX42: 156.4 | BY42: 198 | BZ42: 163.2 | CA42: 120.6 | CB42: 172.2 | CC42: 156.7 | CD42: 180 | CE42: 170.2 | CF42: 196.5 | CG42: 165.7 | CH42: 150.4 | CI42: 163.4 | CJ42: 165.5 | CK42: 163 | CL42: 157.4 | CM42: 167.2 | CN42: 153.1 | CO42: 159.5 | CP42: 162 | CQ42: 164.2 | CR42: 159.4 | CS42: 167.96154 | CT42: 178 | CU42: 161.45 | CV42: 165.7 | CW42: 159.83333 | CX42: 165.5 | CY42: 0.003030303 | CZ42: =VLOOKUP(BR42,'OIL PRICE'!$A$1:$B$27,2,0) -> 94.07
A43: Rural+Urban | B43: 2014 | C43: February | D43: 120.2 | E43: 119.2 | F43: 122.5 | G43: 115.1 | H43: 106.6 | I43: 115.4 | J43: 114.5 | K43: 109.3 | L43: 99.2 | M43: 111.4 | N43: 112.6 | O43: 118.8 | P43: 115.3 | Q43: 114.7 | R43: 116.4 | S43: 113.3 | T43: 115.9 | U43: 112.5 | V43: 112.4 | W43: 112.8 | X43: 110.7 | Y43: 111.1 | Z43: 110.1 | AA43: 111.8 | AB43: 108.7 | AC43: 110.9 | AD43: =AVERAGE(All_India_Index_Upto_April23_CPI_data[[#This Row],[Cereals and products]:[Food and beverages]]) -> 113.85385 | AE43: =AVERAGE(All_India_Index_Upto_April23_CPI_data[[#This Row],[Recreation and amusement]],All_India_Index_Upto_April23_CPI_data[[#This Row],[Pan, tobacco and intoxicants]]) -> 112.4 | AF43: =AVERAGE(All_India_Index_Upto_April23_CPI_data[[#This Row],[Household goods and services]],All_India_Index_Upto_April23_CPI_data[[#This Row],[Housing]]) -> 112.65 | AG43: =AVERAGE(All_India_Index_Upto_April23_CPI_data[[#This Row],[Personal care and effects]],All_India_Index_Upto_April23_CPI_data[[#This Row],[Health]]) -> 109.7 | AH43: =AVERAGE(All_India_Index_Upto_April23_CPI_data[[#This Row],[Clothing]:[Clothing and footwear]]) -> 115.2 | AI43: 113.6 | AJ43: =(All_India_Index_Upto_April23_CPI_data[[#This Row],[General index]]-AI40)/AI40 -> 0 | BO43: Rural+Urban | BP43: 2022 | BQ43: February | BR43: =DATE(BP43,MONTH(DATEVALUE("1 "&BQ43)),1) -> 44593 | BS43: 150 | BT43: 200.6 | BU43: 175.8 | BV43: 160.7 | BW43: 184.9 | BX43: 153.7 | BY43: 169.7 | BZ43: 163.7 | CA43: 118.9 | CB43: 174.3 | CC43: 164.7 | CD43: 178 | CE43: 166.2 | CF43: 192.8 | CG43: 170.8 | CH43: 162.4 | CI43: 169.6 | CJ43: 165.5 | CK43: 165.7 | CL43: 161.8 | CM43: 172.2 | CN43: 156.9 | CO43: 162.1 | CP43: 165.4 | CQ43: 164.4 | CR43: 163.5 | CS43: 166.24615 | CT43: 177.45 | CU43: 163.65 | CV43: 168.3 | CW43: 167.6 | CX43: 166.1 | CY43: 0.0024140012 | CZ43: =VLOOKUP(BR43,'OIL PRICE'!$A$1:$B$27,2,0) -> 94.07
A44: Rural | B44: 2014 | C44: March | D44: 120.1 | E44: 118.1 | F44: 120.7 | G44: 116.1 | H44: 109.3 | I44: 119.6 | J44: 117.9 | K44: 110.2 | L44: 101.2 | M44: 110.7 | N44: 113 | O44: 118.3 | P44: 116.2 | Q44: 114.6 | R44: 117.5 | S44: 114.9 | T44: 117.2 | U44: 0 | V44: 113.4 | W44: 113.4 | X44: 111.4 | Y44: 111.2 | Z44: 110.2 | AA44: 112.4 | AB44: 108.9 | AC44: 111.3 | AD44: =AVERAGE(All_India_Index_Upto_April23_CPI_data[[#This Row],[Cereals and products]:[Food and beverages]]) -> 114.72308 | AE44: =AVERAGE(All_India_Index_Upto_April23_CPI_data[[#This Row],[Recreation and amusement]],All_India_Index_Upto_April23_CPI_data[[#This Row],[Pan, tobacco and intoxicants]]) -> 112.4 | AF44: =AVERAGE(All_India_Index_Upto_April23_CPI_data[[#This Row],[Household goods and services]],All_India_Index_Upto_April23_CPI_data[[#This Row],[Housing]]) -> 56.7 | AG44: =AVERAGE(All_India_Index_Upto_April23_CPI_data[[#This Row],[Personal care and effects]],All_India_Index_Upto_April23_CPI_data[[#This Row],[Health]]) -> 110.15 | AH44: =AVERAGE(All_India_Index_Upto_April23_CPI_data[[#This Row],[Clothing]:[Clothing and footwear]]) -> 116.53333 | AI44: 114.6 | AJ44: =(All_India_Index_Upto_April23_CPI_data[[#This Row],[General index]]-AI41)/AI41 -> 0.0052631579 | BO44: Rural | BP44: 2022 | BQ44: March | BR44: =DATE(BP44,MONTH(DATEVALUE("1 "&BQ44)),1) -> 44621 | BS44: 150.2 | BT44: 208 | BU44: 167.9 | BV44: 162 | BW44: 203.1 | BX44: 155.9 | BY44: 155.8 | BZ44: 164.2 | CA44: 118.1 | CB44: 178.7 | CC44: 171.2 | CD44: 177.4 | CE44: 166.6 | CF44: 192.3 | CG44: 175.4 | CH44: 173.2 | CI44: 175.1 | CJ44: 0 | CK44: 168.9 | CL44: 166.5 | CM44: 176 | CN44: 162 | CO44: 166.6 | CP44: 170.6 | CQ44: 167.4 | CR44: 168.3 | CS44: 167.62308 | CT44: 179.45 | CU44: 83.25 | CV44: 171.7 | CW44: 174.56667 | CX44: 168.7 | CY44: 0.0119976 | CZ44: =VLOOKUP(BR44,'OIL PRICE'!$A$1:$B$27,2,0) -> 112.87
A45: Urban | B45: 2014 | C45: March | D45: 122.1 | E45: 121.4 | F45: 121.5 | G45: 116.2 | H45: 102.8 | I45: 117.7 | J45: 113.3 | K45: 108.9 | L45: 96.3 | M45: 114.1 | N45: 112.2 | O45: 120.5 | P45: 116 | Q45: 116.7 | R45: 115.8 | S45: 112.1 | T45: 115.2 | U45: 113.2 | V45: 110.9 | W45: 113 | X45: 110.8 | Y45: 111.6 | Z45: 110.9 | AA45: 111.8 | AB45: 109.2 | AC45: 111.4 | AD45: =AVERAGE(All_India_Index_Upto_April23_CPI_data[[#This Row],[Cereals and products]:[Food and beverages]]) -> 114.07692 | AE45: =AVERAGE(All_India_Index_Upto_April23_CPI_data[[#This Row],[Recreation and amusement]],All_India_Index_Upto_April23_CPI_data[[#This Row],[Pan, tobacco and intoxicants]]) -> 113.8 | AF45: =AVERAGE(All_India_Index_Upto_April23_CPI_data[[#This Row],[Household goods and services]],All_India_Index_Upto_April23_CPI_data[[#This Row],[Housing]]) -> 113.1 | AG45: =AVERAGE(All_India_Index_Upto_April23_CPI_data[[#This Row],[Personal care and effects]],All_India_Index_Upto_April23_CPI_data[[#This Row],[Health]]) -> 110 | AH45: =AVERAGE(All_India_Index_Upto_April23_CPI_data[[#This Row],[Clothing]:[Clothing and footwear]]) -> 114.36667 | AI45: 113.7 | AJ45: =(All_India_Index_Upto_April23_CPI_data[[#This Row],[General index]]-AI42)/AI42 -> 0.0053050398 | BO45: Urban | BP45: 2022 | BQ45: March | BR45: =DATE(BP45,MONTH(DATEVALUE("1 "&BQ45)),1) -> 44621 | BS45: 153.7 | BT45: 215.8 | BU45: 167.7 | BV45: 162.6 | BW45: 180 | BX45: 159.6 | BY45: 188.4 | BZ45: 163.4 | CA45: 120.3 | CB45: 174.7 | CC45: 157.1 | CD45: 181.5 | CE45: 171.5 | CF45: 197.5 | CG45: 167.1 | CH45: 152.6 | CI45: 164.9 | CJ45: 165.3 | CK45: 164.5 | CL45: 158.6 | CM45: 168.2 | CN45: 154.2 | CO45: 160.8 | CP45: 162.7 | CQ45: 166.8 | CR45: 160.6 | CS45: 168.94615 | CT45: 179.15 | CU45: 161.95 | CV45: 167.5 | CW45: 161.53333 | CX45: 166.5 | CY45: 0.0060422961 | CZ45: =VLOOKUP(BR45,'OIL PRICE'!$A$1:$B$27,2,0) -> 112.87
A46: Rural+Urban | B46: 2014 | C46: March | D46: 120.7 | E46: 119.3 | F46: 121 | G46: 116.1 | H46: 106.9 | I46: 118.7 | J46: 116.3 | K46: 109.8 | L46: 99.6 | M46: 111.8 | N46: 112.7 | O46: 119.3 | P46: 116.1 | Q46: 115.2 | R46: 116.8 | S46: 113.7 | T46: 116.4 | U46: 113.2 | V46: 112.5 | W46: 113.2 | X46: 111.2 | Y46: 111.4 | Z46: 110.6 | AA46: 112 | AB46: 109 | AC46: 111.3 | AD46: =AVERAGE(All_India_Index_Upto_April23_CPI_data[[#This Row],[Cereals and products]:[Food and beverages]]) -> 114.48462 | AE46: =AVERAGE(All_India_Index_Upto_April23_CPI_data[[#This Row],[Recreation and amusement]],All_India_Index_Upto_April23_CPI_data[[#This Row],[Pan, tobacco and intoxicants]]) -> 112.9 | AF46: =AVERAGE(All_India_Index_Upto_April23_CPI_data[[#This Row],[Household goods and services]],All_India_Index_Upto_April23_CPI_data[[#This Row],[Housing]]) -> 113.2 | AG46: =AVERAGE(All_India_Index_Upto_April23_CPI_data[[#This Row],[Personal care and effects]],All_India_Index_Upto_April23_CPI_data[[#This Row],[Health]]) -> 110.1 | AH46: =AVERAGE(All_India_Index_Upto_April23_CPI_data[[#This Row],[Clothing]:[Clothing and footwear]]) -> 115.63333 | AI46: 114.2 | AJ46: =(All_India_Index_Upto_April23_CPI_data[[#This Row],[General index]]-AI43)/AI43 -> 0.0052816901 | BO46: Rural+Urban | BP46: 2022 | BQ46: March | BR46: =DATE(BP46,MONTH(DATEVALUE("1 "&BQ46)),1) -> 44621 | BS46: 151.3 | BT46: 210.7 | BU46: 167.8 | BV46: 162.2 | BW46: 194.6 | BX46: 157.6 | BY46: 166.9 | BZ46: 163.9 | CA46: 118.8 | CB46: 177.4 | CC46: 165.3 | CD46: 179.3 | CE46: 168.4 | CF46: 193.7 | CG46: 172.1 | CH46: 164.6 | CI46: 171.1 | CJ46: 165.3 | CK46: 167.2 | CL46: 162.8 | CM46: 173 | CN46: 157.9 | CO46: 163.3 | CP46: 166 | CQ46: 167.2 | CR46: 164.6 | CS46: 168.01538 | CT46: 178.5 | CU46: 164.05 | CV46: 170.1 | CW46: 169.26667 | CX46: 167.7 | CY46: 0.0096327514 | CZ46: =VLOOKUP(BR46,'OIL PRICE'!$A$1:$B$27,2,0) -> 112.87
A47: Rural | B47: 2014 | C47: April | D47: 120.2 | E47: 118.9 | F47: 118.1 | G47: 117 | H47: 109.7 | I47: 125.5 | J47: 120.5 | K47: 111 | L47: 102.6 | M47: 111.2 | N47: 113.5 | O47: 118.7 | P47: 117.2 | Q47: 115.4 | R47: 118.1 | S47: 116.1 | T47: 117.8 | U47: 0 | V47: 113.4 | W47: 113.7 | X47: 111.8 | Y47: 111.2 | Z47: 110.5 | AA47: 113 | AB47: 108.9 | AC47: 111.5 | AD47: =AVERAGE(All_India_Index_Upto_April23_CPI_data[[#This Row],[Cereals and products]:[Food and beverages]]) -> 115.7 | AE47: =AVERAGE(All_India_Index_Upto_April23_CPI_data[[#This Row],[Recreation and amusement]],All_India_Index_Upto_April23_CPI_data[[#This Row],[Pan, tobacco and intoxicants]]) -> 112.95 | AF47: =AVERAGE(All_India_Index_Upto_April23_CPI_data[[#This Row],[Household goods and services]],All_India_Index_Upto_April23_CPI_data[[#This Row],[Housing]]) -> 56.85 | AG47: =AVERAGE(All_India_Index_Upto_April23_CPI_data[[#This Row],[Personal care and effects]],All_India_Index_Upto_April23_CPI_data[[#This Row],[Health]]) -> 110.35 | AH47: =AVERAGE(All_India_Index_Upto_April23_CPI_data[[#This Row],[Clothing]:[Clothing and footwear]]) -> 117.33333 | AI47: 115.4 | AJ47: =(All_India_Index_Upto_April23_CPI_data[[#This Row],[General index]]-AI44)/AI44 -> 0.0069808028 | BO47: Rural | BP47: 2022 | BQ47: April | BR47: =DATE(BP47,MONTH(DATEVALUE("1 "&BQ47)),1) -> 44652 | BS47: 151.8 | BT47: 209.7 | BU47: 164.5 | BV47: 163.8 | BW47: 207.4 | BX47: 169.7 | BY47: 153.6 | BZ47: 165.1 | CA47: 118.2 | CB47: 182.9 | CC47: 172.4 | CD47: 178.9 | CE47: 168.6 | CF47: 192.8 | CG47: 177.5 | CH47: 175.1 | CI47: 177.1 | CJ47: 0 | CK47: 173.3 | CL47: 167.7 | CM47: 177 | CN47: 166.2 | CO47: 167.2 | CP47: 170.9 | CQ47: 169 | CR47: 170.2 | CS47: 169.73846 | CT47: 180 | CU47: 83.85 | CV47: 173 | CW47: 176.56667 | CX47: 170.8 | CY47: 0.012448133 | CZ47: =VLOOKUP(BR47,'OIL PRICE'!$A$1:$B$27,2,0) -> 102.97
A48: Urban | B48: 2014 | C48: April | D48: 122.5 | E48: 121.7 | F48: 113.3 | G48: 117 | H48: 103.1 | I48: 126.7 | J48: 121.2 | K48: 111 | L48: 100.3 | M48: 115.3 | N48: 112.7 | O48: 121 | P48: 118.2 | Q48: 117.6 | R48: 116.3 | S48: 112.5 | T48: 115.7 | U48: 113.9 | V48: 110.9 | W48: 113.4 | X48: 111 | Y48: 111.2 | Z48: 111.2 | AA48: 112.5 | AB48: 109.1 | AC48: 111.4 | AD48: =AVERAGE(All_India_Index_Upto_April23_CPI_data[[#This Row],[Cereals and products]:[Food and beverages]]) -> 115.69231 | AE48: =AVERAGE(All_India_Index_Upto_April23_CPI_data[[#This Row],[Recreation and amusement]],All_India_Index_Upto_April23_CPI_data[[#This Row],[Pan, tobacco and intoxicants]]) -> 114.4 | AF48: =AVERAGE(All_India_Index_Upto_April23_CPI_data[[#This Row],[Household goods and services]],All_India_Index_Upto_April23_CPI_data[[#This Row],[Housing]]) -> 113.65 | AG48: =AVERAGE(All_India_Index_Upto_April23_CPI_data[[#This Row],[Personal care and effects]],All_India_Index_Upto_April23_CPI_data[[#This Row],[Health]]) -> 110.05 | AH48: =AVERAGE(All_India_Index_Upto_April23_CPI_data[[#This Row],[Clothing]:[Clothing and footwear]]) -> 114.83333 | AI48: 114.7 | AJ48: =(All_India_Index_Upto_April23_CPI_data[[#This Row],[General index]]-AI45)/AI45 -> 0.0087950748 | BO48: Urban | BP48: 2022 | BQ48: April | BR48: =DATE(BP48,MONTH(DATEVALUE("1 "&BQ48)),1) -> 44652 | BS48: 155.4 | BT48: 215.8 | BU48: 164.6 | BV48: 164.2 | BW48: 186 | BX48: 175.9 | BY48: 190.7 | BZ48: 164 | CA48: 120.5 | CB48: 178 | CC48: 157.5 | CD48: 183.3 | CE48: 174.5 | CF48: 197.1 | CG48: 168.4 | CH48: 154.5 | CI48: 166.3 | CJ48: 167 | CK48: 170.5 | CL48: 159.8 | CM48: 169 | CN48: 159.3 | CO48: 162.2 | CP48: 164 | CQ48: 168.4 | CR48: 163.1 | CS48: 171.56923 | CT48: 179.65 | CU48: 163.4 | CV48: 168.7 | CW48: 163.06667 | CX48: 169.2 | CY48: 0.016216216 | CZ48: =VLOOKUP(BR48,'OIL PRICE'!$A$1:$B$27,2,0) -> 102.97
A49: Rural+Urban | B49: 2014 | C49: April | D49: 120.9 | E49: 119.9 | F49: 116.2 | G49: 117 | H49: 107.3 | I49: 126.1 | J49: 120.7 | K49: 111 | L49: 101.8 | M49: 112.6 | N49: 113.2 | O49: 119.8 | P49: 117.6 | Q49: 116 | R49: 117.4 | S49: 114.6 | T49: 117 | U49: 113.9 | V49: 112.5 | W49: 113.6 | X49: 111.5 | Y49: 111.2 | Z49: 110.9 | AA49: 112.7 | AB49: 109 | AC49: 111.5 | AD49: =AVERAGE(All_India_Index_Upto_April23_CPI_data[[#This Row],[Cereals and products]:[Food and beverages]]) -> 115.7 | AE49: =AVERAGE(All_India_Index_Upto_April23_CPI_data[[#This Row],[Recreation and amusement]],All_India_Index_Upto_April23_CPI_data[[#This Row],[Pan, tobacco and intoxicants]]) -> 113.45 | AF49: =AVERAGE(All_India_Index_Upto_April23_CPI_data[[#This Row],[Household goods and services]],All_India_Index_Upto_April23_CPI_data[[#This Row],[Housing]]) -> 113.75 | AG49: =AVERAGE(All_India_Index_Upto_April23_CPI_data[[#This Row],[Personal care and effects]],All_India_Index_Upto_April23_CPI_data[[#This Row],[Health]]) -> 110.25 | AH49: =AVERAGE(All_India_Index_Upto_April23_CPI_data[[#This Row],[Clothing]:[Clothing and footwear]]) -> 116.33333 | AI49: 115.1 | AJ49: =(All_India_Index_Upto_April23_CPI_data[[#This Row],[General index]]-AI46)/AI46 -> 0.0078809107 | BO49: Rural+Urban | BP49: 2022 | BQ49: April | BR49: =DATE(BP49,MONTH(DATEVALUE("1 "&BQ49)),1) -> 44652 | BS49: 152.9 | BT49: 211.8 | BU49: 164.5 | BV49: 163.9 | BW49: 199.5 | BX49: 172.6 | BY49: 166.2 | BZ49: 164.7 | CA49: 119 | CB49: 181.3 | CC49: 166.2 | CD49: 180.9 | CE49: 170.8 | CF49: 193.9 | CG49: 173.9 | CH49: 166.5 | CI49: 172.8 | CJ49: 167 | CK49: 172.2 | CL49: 164 | CM49: 174 | CN49: 162.6 | CO49: 164.4 | CP49: 166.9 | CQ49: 168.8 | CR49: 166.8 | CS49: 170.33077 | CT49: 179.15 | CU49: 165.5 | CV49: 171.4 | CW49: 171.06667 | CX49: 170.1 | CY49: 0.01431127 | CZ49: =VLOOKUP(BR49,'OIL PRICE'!$A$1:$B$27,2,0) -> 102.97
A50: Rural | B50: 2014 | C50: May | D50: 120.3 | E50: 120.2 | F50: 116.9 | G50: 118 | H50: 110.1 | I50: 126.3 | J50: 123.9 | K50: 111.5 | L50: 103.5 | M50: 111.6 | N50: 114.2 | O50: 119.2 | P50: 118.2 | Q50: 116.3 | R50: 118.7 | S50: 116.8 | T50: 118.5 | U50: 0 | V50: 113.4 | W50: 114.1 | X50: 112.1 | Y50: 111.4 | Z50: 110.9 | AA50: 113.1 | AB50: 108.9 | AC50: 111.8 | AD50: =AVERAGE(All_India_Index_Upto_April23_CPI_data[[#This Row],[Cereals and products]:[Food and beverages]]) -> 116.45385 | AE50: =AVERAGE(All_India_Index_Upto_April23_CPI_data[[#This Row],[Recreation and amusement]],All_India_Index_Upto_April23_CPI_data[[#This Row],[Pan, tobacco and intoxicants]]) -> 113.6 | AF50: =AVERAGE(All_India_Index_Upto_April23_CPI_data[[#This Row],[Household goods and services]],All_India_Index_Upto_April23_CPI_data[[#This Row],[Housing]]) -> 57.05 | AG50: =AVERAGE(All_India_Index_Upto_April23_CPI_data[[#This Row],[Personal care and effects]],All_India_Index_Upto_April23_CPI_data[[#This Row],[Health]]) -> 110.5 | AH50: =AVERAGE(All_India_Index_Upto_April23_CPI_data[[#This Row],[Clothing]:[Clothing and footwear]]) -> 118 | AI50: 116 | AJ50: =(All_India_Index_Upto_April23_CPI_data[[#This Row],[General index]]-AI47)/AI47 -> 0.0051993068 | BO50: Rural | BP50: 2022 | BQ50: May | BR50: =DATE(BP50,MONTH(DATEVALUE("1 "&BQ50)),1) -> 44682 | BS50: 152.9 | BT50: 214.7 | BU50: 161.4 | BV50: 164.6 | BW50: 209.9 | BX50: 168 | BY50: 160.4 | BZ50: 165 | CA50: 118.9 | CB50: 186.6 | CC50: 173.2 | CD50: 180.4 | CE50: 170.8 | CF50: 192.9 | CG50: 179.3 | CH50: 177.2 | CI50: 179 | CJ50: 0 | CK50: 175.3 | CL50: 168.9 | CM50: 177.7 | CN50: 167.1 | CO50: 167.6 | CP50: 171.8 | CQ50: 168.5 | CR50: 170.9 | CS50: 171.29231 | CT50: 180.25 | CU50: 84.45 | CV50: 173.1 | CW50: 178.5 | CX50: 172.5 | CY50: 0.0099531616 | CZ50: =VLOOKUP(BR50,'OIL PRICE'!$A$1:$B$27,2,0) -> 109.51
A51: Urban | B51: 2014 | C51: May | D51: 122.7 | E51: 124.1 | F51: 114.2 | G51: 119.1 | H51: 103.5 | I51: 129.2 | J51: 127 | K51: 112.6 | L51: 101.3 | M51: 117 | N51: 112.9 | O51: 121.7 | P51: 120 | Q51: 118.3 | R51: 116.8 | S51: 112.9 | T51: 116.2 | U51: 114.3 | V51: 111.1 | W51: 114.1 | X51: 111.2 | Y51: 111.3 | Z51: 111.5 | AA51: 112.9 | AB51: 109.3 | AC51: 111.7 | AD51: =AVERAGE(All_India_Index_Upto_April23_CPI_data[[#This Row],[Cereals and products]:[Food and beverages]]) -> 117.33077 | AE51: =AVERAGE(All_India_Index_Upto_April23_CPI_data[[#This Row],[Recreation and amusement]],All_India_Index_Upto_April23_CPI_data[[#This Row],[Pan, tobacco and intoxicants]]) -> 114.9 | AF51: =AVERAGE(All_India_Index_Upto_April23_CPI_data[[#This Row],[Household goods and services]],All_India_Index_Upto_April23_CPI_data[[#This Row],[Housing]]) -> 114.2 | AG51: =AVERAGE(All_India_Index_Upto_April23_CPI_data[[#This Row],[Personal care and effects]],All_India_Index_Upto_April23_CPI_data[[#This Row],[Health]]) -> 110.25 | AH51: =AVERAGE(All_India_Index_Upto_April23_CPI_data[[#This Row],[Clothing]:[Clothing and footwear]]) -> 115.3 | AI51: 115.6 | AJ51: =(All_India_Index_Upto_April23_CPI_data[[#This Row],[General index]]-AI48)/AI48 -> 0.0078465562 | BO51: Urban | BP51: 2022 | BQ51: May | BR51: =DATE(BP51,MONTH(DATEVALUE("1 "&BQ51)),1) -> 44682 | BS51: 156.7 | BT51: 221.2 | BU51: 164.1 | BV51: 165.4 | BW51: 189.5 | BX51: 174.5 | BY51: 203.2 | BZ51: 164.1 | CA51: 121.2 | CB51: 181.4 | CC51: 158.5 | CD51: 184.9 | CE51: 177.5 | CF51: 197.5 | CG51: 170 | CH51: 155.9 | CI51: 167.8 | CJ51: 167.5 | CK51: 173.5 | CL51: 161.1 | CM51: 170.1 | CN51: 159.4 | CO51: 163.2 | CP51: 165.2 | CQ51: 168.2 | CR51: 163.8 | CS51: 174.01538 | CT51: 180.35 | CU51: 164.3 | CV51: 169.15 | CW51: 164.56667 | CX51: 170.8 | CY51: 0.0094562648 | CZ51: =VLOOKUP(BR51,'OIL PRICE'!$A$1:$B$27,2,0) -> 109.51
